Workbook

Sheet Dashboard
A1: DASHBOARD — MEMBRESÍAS VIP |VENTAS POR CALL CENTER
A3: TOTAL MEMBRESÍAS | D3: VALOR VENDIDO | G3: 3 MESES
A4: =COUNTIFS(Ventas!G2:G301,"<>",Ventas!I2:I301,"<>Anulado") -> 38 | D4: =SUMIFS(Ventas!H2:H301,Ventas!G2:G301,"<>",Ventas!I2:I301,"<>Anulado") -> 9180000 | G4: =COUNTIFS(Ventas!G2:G301,"3 Meses",Ventas!I2:I301,"<>Anulado") -> 36
A6: 6 MESES | D6: PAGADAS | G6: TICKET PROMEDIO
A7: =COUNTIFS(Ventas!G2:G301,"6 Meses",Ventas!I2:I301,"<>Anulado") -> 2 | D7: =COUNTIFS(Ventas!G2:G301,"<>",Ventas!I2:I301,"Pagado") -> 38 | G7: =IFERROR(B5/B4,0) -> 0
A9: VENTAS POR ASESORA | H9: MIX DE PRODUCTO
A10: Asesora | B10: 3 meses | C10: 6 meses | D10: Total | E10: Valor vendido | F10: % participación | H10: Membresía | I10: Cantidad | J10: Valor
A11: Luisa | B11: =COUNTIFS(Ventas!B2:B301,A11,Ventas!G2:G301,"3 Meses",Ventas!I2:I301,"<>Anulado") -> 7 | C11: =COUNTIFS(Ventas!B2:B301,A11,Ventas!G2:G301,"6 Meses",Ventas!I2:I301,"<>Anulado") -> 0 | D11: =B11+C11 -> 7 | E11: =SUMIFS(Ventas!H2:H301,Ventas!B2:B301,A11,Ventas!I2:I301,"<>Anulado") -> 1645000 | F11: =IFERROR(D11/$D$16,0) -> 0.18421053 | H11: 3 Meses | I11: =G4 -> 36 | J11: =I11*235000 -> 8460000
A12: Mariana | B12: =COUNTIFS(Ventas!B2:B301,A12,Ventas!G2:G301,"3 Meses",Ventas!I2:I301,"<>Anulado") -> 2 | C12: =COUNTIFS(Ventas!B2:B301,A12,Ventas!G2:G301,"6 Meses",Ventas!I2:I301,"<>Anulado") -> 0 | D12: =B12+C12 -> 2 | E12: =SUMIFS(Ventas!H2:H301,Ventas!B2:B301,A12,Ventas!I2:I301,"<>Anulado") -> 470000 | F12: =IFERROR(D12/$D$16,0) -> 0.052631579 | H12: 6 Meses | I12: =A7 -> 2 | J12: =I12*360000 -> 720000
A13: Isabel | B13: 9 | C13: 2 | D13: =B13+C13 -> 11 | E13: =SUMIFS(Ventas!H2:H301,Ventas!B2:B301,A13,Ventas!I2:I301,"<>Anulado") -> 2835000 | F13: =IFERROR(D13/$D$16,0) -> 0.28947368
A14: Stefanya | B14: =COUNTIFS(Ventas!B2:B301,A14,Ventas!G2:G301,"3 Meses",Ventas!I2:I301,"<>Anulado") -> 7 | C14: 0 | D14: =B14+C14 -> 7 | E14: =SUMIFS(Ventas!H2:H301,Ventas!B2:B301,A14,Ventas!I2:I301,"<>Anulado") -> 1645000 | F14: =IFERROR(D14/$D$16,0) -> 0.18421053
A15: Yulianis | B15: =COUNTIFS(Ventas!B2:B301,A15,Ventas!G2:G301,"3 Meses",Ventas!I2:I301,"<>Anulado") -> 11 | C15: =COUNTIFS(Ventas!B2:B301,A15,Ventas!G2:G301,"6 Meses",Ventas!I2:I301,"<>Anulado") -> 0 | D15: =B15+C15 -> 11 | E15: =SUMIFS(Ventas!H2:H301,Ventas!B2:B301,A15,Ventas!I2:I301,"<>Anulado") -> 2585000 | F15: =IFERROR(D15/$D$16,0) -> 0.28947368 | H15: CONTROL DE CALIDAD
A16: TOTAL | B16: =SUM(B11:B15) -> 36 | C16: =SUM(C11:C15) -> 2 | D16: =SUM(D11:D15) -> 38 | E16: =SUM(E11:E15) -> 9180000 | F16: =SUM(F11:F15) -> 1 | H16: Ventas sin sede | I16: =COUNTIFS(Ventas!F2:F301,"",Ventas!G2:G301,"<>") -> 0
H17: Ventas sin cédula | I17: =COUNTIFS(Ventas!D2:D301,"",Ventas!G2:G301,"<>") -> 0
H18: Pagos pendientes | I18: =COUNTIFS(Ventas!I2:I301,"Pendiente") -> 0
A19: VENTAS POR SEDE | H19: Pagos anulados | I19: =COUNTIFS(Ventas!I2:I301,"Anulado") -> 0
A20: Sede | B20: Membresías | C20: 3 meses | D20: 6 meses | E20: Valor vendido | F20: % participación
A21: TESORO | B21: =COUNTIFS(Ventas!F2:F301,"TESORO",Ventas!G2:G301,"<>",Ventas!I2:I301,"<>Anulado") -> 9 | C21: =COUNTIFS(Ventas!F2:F301,"TESORO",Ventas!G2:G301,"3 Meses",Ventas!I2:I301,"<>Anulado") -> 8 | D21: =COUNTIFS(Ventas!F2:F301,"TESORO",Ventas!G2:G301,"6 Meses",Ventas!I2:I301,"<>Anulado") -> 1 | E21: =SUMIFS(Ventas!H2:H301,Ventas!F2:F301,"TESORO",Ventas!I2:I301,"<>Anulado") -> 2240000 | F21: =IFERROR(B21/$B$30,0) -> 0.375
A22: CHICO | B22: =COUNTIFS(Ventas!F2:F301,"CHICO",Ventas!G2:G301,"<>",Ventas!I2:I301,"<>Anulado") -> 9 | C22: =COUNTIFS(Ventas!F2:F301,"CHICO",Ventas!G2:G301,"3 Meses",Ventas!I2:I301,"<>Anulado") -> 9 | D22: =COUNTIFS(Ventas!F2:F301,"CHICO",Ventas!G2:G301,"6 Meses",Ventas!I2:I301,"<>Anulado") -> 0 | E22: =SUMIFS(Ventas!H2:H301,Ventas!F2:F301,"CHICO",Ventas!I2:I301,"<>Anulado") -> 2115000 | F22: =IFERROR(B22/$B$30,0) -> 0.375
A23: SANTA FE | B23: =COUNTIFS(Ventas!F2:F301,"SANTA FE",Ventas!G2:G301,"<>",Ventas!I2:I301,"<>Anulado") -> 3 | C23: =COUNTIFS(Ventas!F2:F301,"SANTA FE",Ventas!G2:G301,"3 Meses",Ventas!I2:I301,"<>Anulado") -> 3 | D23: =COUNTIFS(Ventas!F2:F301,"SANTA FE",Ventas!G2:G301,"6 Meses",Ventas!I2:I301,"<>Anulado") -> 0 | E23: =SUMIFS(Ventas!H2:H301,Ventas!F2:F301,"SANTA FE",Ventas!I2:I301,"<>Anulado") -> 705000 | F23: =IFERROR(B23/$B$30,0) -> 0.125
A24: LAURELES | B24: =COUNTIFS(Ventas!F2:F301,"LAURELES",Ventas!G2:G301,"<>",Ventas!I2:I301,"<>Anulado") -> 1 | C24: =COUNTIFS(Ventas!F2:F301,"LAURELES",Ventas!G2:G301,"3 Meses",Ventas!I2:I301,"<>Anulado") -> 1 | D24: =COUNTIFS(Ventas!F2:F301,"LAURELES",Ventas!G2:G301,"6 Meses",Ventas!I2:I301,"<>Anulado") -> 0 | E24: =SUMIFS(Ventas!H2:H301,Ventas!F2:F301,"LAURELES",Ventas!I2:I301,"<>Anulado") -> 235000 | F24: =IFERROR(B24/$B$30,0) -> 0.041666667
A25: SABANETA | B25: =COUNTIFS(Ventas!F2:F301,"SABANETA",Ventas!G2:G301,"<>",Ventas!I2:I301,"<>Anulado") -> 2 | C25: =COUNTIFS(Ventas!F2:F301,"SABANETA",Ventas!G2:G301,"3 Meses",Ventas!I2:I301,"<>Anulado") -> 1 | D25: =COUNTIFS(Ventas!F2:F301,"SABANETA",Ventas!G2:G301,"6 Meses",Ventas!I2:I301,"<>Anulado") -> 1 | E25: =SUMIFS(Ventas!H2:H301,Ventas!F2:F301,"SABANETA",Ventas!I2:I301,"<>Anulado") -> 595000 | F25: =IFERROR(B25/$B$30,0) -> 0.083333333
A26: MEDELLÍN | B26: =COUNTIFS(Ventas!F2:F301,"MEDELLÍN",Ventas!G2:G301,"<>",Ventas!I2:I301,"<>Anulado") -> 0 | C26: =COUNTIFS(Ventas!F2:F301,"MEDELLÍN",Ventas!G2:G301,"3 Meses",Ventas!I2:I301,"<>Anulado") -> 0 | D26: =COUNTIFS(Ventas!F2:F301,"MEDELLÍN",Ventas!G2:G301,"6 Meses",Ventas!I2:I301,"<>Anulado") -> 0 | E26: =SUMIFS(Ventas!H2:H301,Ventas!F2:F301,"MEDELLÍN",Ventas!I2:I301,"<>Anulado") -> 0 | F26: =IFERROR(B26/$B$30,0) -> 0
A27: RIONEGRO | B27: =COUNTIFS(Ventas!F2:F301,"RIONEGRO",Ventas!G2:G301,"<>",Ventas!I2:I301,"<>Anulado") -> 0 | C27: =COUNTIFS(Ventas!F2:F301,"RIONEGRO",Ventas!G2:G301,"3 Meses",Ventas!I2:I301,"<>Anulado") -> 0 | D27: =COUNTIFS(Ventas!F2:F301,"RIONEGRO",Ventas!G2:G301,"6 Meses",Ventas!I2:I301,"<>Anulado") -> 0 | E27: =SUMIFS(Ventas!H2:H301,Ventas!F2:F301,"RIONEGRO",Ventas!I2:I301,"<>Anulado") -> 0 | F27: =IFERROR(B27/$B$30,0) -> 0
A28: BOGOTÁ | B28: =COUNTIFS(Ventas!F2:F301,"BOGOTÁ",Ventas!G2:G301,"<>",Ventas!I2:I301,"<>Anulado") -> 0 | C28: =COUNTIFS(Ventas!F2:F301,"BOGOTÁ",Ventas!G2:G301,"3 Meses",Ventas!I2:I301,"<>Anulado") -> 0 | D28: =COUNTIFS(Ventas!F2:F301,"BOGOTÁ",Ventas!G2:G301,"6 Meses",Ventas!I2:I301,"<>Anulado") -> 0 | E28: =SUMIFS(Ventas!H2:H301,Ventas!F2:F301,"BOGOTÁ",Ventas!I2:I301,"<>Anulado") -> 0 | F28: =IFERROR(B28/$B$30,0) -> 0
A29: SIN REGISTRO | B29: =COUNTIFS(Ventas!F2:F301,"",Ventas!G2:G301,"<>",Ventas!I2:I301,"<>Anulado") -> 0 | C29: =COUNTIFS(Ventas!F2:F301,"",Ventas!G2:G301,"3 Meses",Ventas!I2:I301,"<>Anulado") -> 0 | D29: =COUNTIFS(Ventas!F2:F301,"",Ventas!G2:G301,"6 Meses",Ventas!I2:I301,"<>Anulado") -> 0 | E29: =SUMIFS(Ventas!H2:H301,Ventas!F2:F301,"",Ventas!I2:I301,"<>Anulado") -> 0 | F29: =IFERROR(B29/$B$30,0) -> 0
A30: TOTAL | B30: =SUM(B21:B29) -> 24 | C30: =SUM(C21:C29) -> 22 | D30: =SUM(D21:D29) -> 2 | E30: =SUM(E21:E29) -> 5890000 | F30: =SUM(F21:F29) -> 1

Sheet Ventas
A1: Fecha de venta | B1: Asesora | C1: Cliente | D1: Cédula | E1: Teléfono | F1: Sede | G1: Membresía | H1: Valor | I1: Estado de pago | J1: Medio de pago | K1: Origen | L1: Observaciones
A2: 46246 | B2: Mariana | C2: MARIA VIRGINIA GONZALES | D2: 25280728 | E2: 3003661818 | F2: TESORO | G2: 3 Meses | H2: 235000 | I2: Pagado | J2: Wompi | K2: WhatsApp | L2: Anticipo ok
A3: 46246 | B3: Isabel | C3: MIGUEL R | D3: 1141515836 | E3: 3176651603 | F3: TESORO | G3: 3 Meses | H3: 235000 | I3: Pagado | J3: Wompi | K3: WhatsApp | L3: Anticipo ok
A4: 46246 | B4: Yulianis | C4: MARCELA DIAZ MORON | D4: 1000087213 | E4: 3022799531 | F4: TESORO | G4: 3 Meses | H4: 235000 | I4: Pagado | J4: Wompi | K4: WhatsApp | L4: Anticipo ok
A5: 46246 | B5: Mariana | C5: VERONICA BETANCUR | D5: 43618669 | E5: 3158696965 | F5: TESORO | G5: 3 Meses | H5: 235000 | I5: Pagado | J5: Wompi | K5: WhatsApp | L5: Anticipo ok
A6: 46246 | B6: Isabel | C6: MAYELI Giraldo | D6: 1152209030 | E6: 3122205469 | F6: LAURELES | G6: 3 Meses | H6: 235000 | I6: Pagado | J6: Wompi | K6: WhatsApp | L6: Anticipo ok
A7: 46246 | B7: Isabel | C7: LAURA M | D7: 1128273216 | E7: 3013374699 | F7: TESORO | G7: 6 Meses | H7: 360000 | I7: Pagado | J7: Wompi | K7: WhatsApp | L7: Anticipo ok
A8: 46246 | B8: Yulianis | C8: CATHERINE GOMEZ | D8: 1020733539 | E8: 3158948090 | F8: CHICO | G8: 3 Meses | H8: 235000 | I8: Pagado | J8: Wompi | K8: WhatsApp | L8: Anticipo ok
A9: 46247 | B9: Yulianis | C9: VERONICA MONTEJO | D9: 1020808920 | E9: 3138708086 | F9: CHICO | G9: 3 Meses | H9: 235000 | I9: Pagado | J9: Wompi | K9: WhatsApp | L9: Anticipo ok
A10: 46247 | B10: Luisa | C10: MONICA YEPEZ | D10: 31433086 | E10: 3204923368 | F10: CHICO | G10: 3 Meses | H10: 235000 | I10: Pagado | J10: Wompi | K10: WhatsApp | L10: Anticipo ok
A11: 46247 | B11: Isabel | C11: FANNY B | D11: 20392261 | E11: 3114438844 | F11: SANTA FE | G11: 3 Meses | H11: 235000 | I11: Pagado | J11: Wompi | K11: WhatsApp | L11: Anticipo ok
A12: 46247 | B12: Luisa | C12: LEIDY AGUDELO | D12: 1039454271 | E12: 3014449046 | F12: CHICO | G12: 3 Meses | H12: 235000 | I12: Pagado | J12: Wompi | K12: WhatsApp | L12: Anticipo ok
A13: 46248 | B13: Stefanya | C13: JUAN CARLOS GOMEZ | D13: 71227532 | E13: 3116055923 | F13: TESORO | G13: 3 Meses | H13: 235000 | I13: Pagado | J13: Wompi | K13: WhatsApp | L13: Anticipo ok
A14: 46248 | B14: Luisa | C14: LINA SANCHEZ | D14: 1000236113 | E14: 3186426572 | F14: SANTA FE | G14: 3 Meses | H14: =IF(G14="","",IF(G14="3 Meses",235000,IF(G14="6 Meses",360000,""))) -> 235000 | I14: Pagado | J14: Wompi | K14: WhatsApp | L14: Anticipo ok
A15: 46248 | B15: Yulianis | C15: JIMENA CACERES | D15: 52151950 | E15: 3012869571 | F15: CHICO | G15: 3 Meses | H15: 235000 | I15: Pagado | J15: Wompi | K15: WhatsApp | L15: Anticipo ok
A16: 46249 | B16: Yulianis | C16: DANIELA DIAZ | D16: 1000087242 | E16: 3012189425 | F16: TESORO | G16: 3 Meses | H16: 235000 | I16: Pagado | J16: Wompi | K16: WhatsApp | L16: Anticipo ok
A17: 46249 | B17: Isabel | C17: VALERIA LOPEZ | D17: 1031641493 | E17: 3208420524 | F17: SALITRE | G17: 3 Meses | H17: =IF(G17="","",IF(G17="3 Meses",235000,IF(G17="6 Meses",360000,""))) -> 235000 | I17: Pagado | J17: Wompi | K17: WhatsApp | L17: Anticipo ok
A18: 46068 | B18: Luisa | C18: BIBIANA ACOSTA | D18: 1072652000 | E18: 3115093293 | F18: SANTA FE | G18: 3 Meses | H18: =IF(G18="","",IF(G18="3 Meses",235000,IF(G18="6 Meses",360000,""))) -> 235000 | I18: Pagado | J18: Wompi | K18: WhatsApp | L18: Anticipo ok
A19: 46071 | B19: Stefanya | C19: MARIA CARDENAS | D19: 64740591 | E19: 3164731399 | F19: CHICO | G19: 3 Meses | H19: 235000 | I19: Pagado | J19: Wompi | K19: WhatsApp | L19: Anticipo ok
A20: 46253 | B20: Isabel | C20: MIRTHA CERCHAR | D20: 36725102 | E20: 3017543920 | F20: BARRANQUILLA | G20: 3 Meses | H20: 235000 | I20: Pagado | J20: Wompi | K20: WhatsApp | L20: Anticipo ok
A21: 46253 | B21: Isabel | C21: JENNY BARON | D21: 63531248 | E21: 3166904925 | F21: TESORO | G21: 3 Meses | H21: =IF(G21="","",IF(G21="3 Meses",235000,IF(G21="6 Meses",360000,""))) -> 235000 | I21: Pagado | J21: Wompi | K21: WhatsApp | L21: Anticipo ok
A22: 46253 | B22: Isabel | C22: CINDY VELEZ | D22: 32297437 | E22: 3008400826 | F22: SABANETA | G22: 3 Meses | H22: =IF(G22="","",IF(G22="3 Meses",235000,IF(G22="6 Meses",360000,""))) -> 235000 | I22: Pagado | J22: Wompi | K22: WhatsApp | L22: Anticipo ok
A23: 46253 | B23: Stefanya | C23: ARLEY PATRICIA RINCON | D23: 1234098195 | E23: 3132196093 | F23: CHICO | G23: 3 Meses | H23: =IF(G23="","",IF(G23="3 Meses",235000,IF(G23="6 Meses",360000,""))) -> 235000 | I23: Pagado | J23: Wompi | K23: WhatsApp | L23: Anticipo ok
A24: 46255 | B24: Yulianis | C24: lAURA ALEJANDRA ROJAS | D24: 1015438721 | E24: 3014081667 | F24: CHICO | G24: 3 Meses | H24: =IF(G24="","",IF(G24="3 Meses",235000,IF(G24="6 Meses",360000,""))) -> 235000 | I24: Pagado | J24: Wompi | K24: WhatsApp | L24: Anticipo ok
A25: 46255 | B25: Isabel | C25: HILIANY MARTINEZ | D25: 1128447197 | E25: 3135905863 | F25: SABANETA | G25: 6 Meses | H25: =IF(G25="","",IF(G25="3 Meses",235000,IF(G25="6 Meses",360000,""))) -> 360000 | I25: Pagado | J25: Wompi | K25: WhatsApp | L25: Anticipo ok
A26: 46256 | B26: Isabel | C26: MARCELA SANTOS | D26: 22449889 | E26: 3007412564 | F26: BARRANQUILLA | G26: 3 Meses | H26: =IF(G26="","",IF(G26="3 Meses",235000,IF(G26="6 Meses",360000,""))) -> 235000 | I26: Pagado | J26: Wompi | K26: WhatsApp | L26: Anticipo ok
A27: 46258 | B27: Luisa | C27: Luisa Tephems | D27: 41934600 | E27: 3158292949 | F27: TERRACINA | G27: 3 Meses | H27: =IF(G27="","",IF(G27="3 Meses",235000,IF(G27="6 Meses",360000,""))) -> 235000 | I27: Pagado | J27: Wompi | K27: WhatsApp | L27: Anticipo ok
A28: 46259 | B28: Stefanya | C28: Eira Ortega | D28: 570784 | E28: 3102974227 | F28: CHICO | G28: 3 Meses | H28: =IF(G28="","",IF(G28="3 Meses",235000,IF(G28="6 Meses",360000,""))) -> 235000 | I28: Pagado | J28: Wompi | K28: WhatsApp | L28: Anticipo ok
A29: 46259 | B29: Isabel | C29: GLORIA ROBLES | D29: 45496929 | E29: 3008007748 | F29: BARRANQUILLA | G29: 3 Meses | H29: =IF(G29="","",IF(G29="3 Meses",235000,IF(G29="6 Meses",360000,""))) -> 235000 | I29: Pagado | J29: Wompi | K29: WhatsApp | L29: Anticipo ok
A30: 46260 | B30: Yulianis | C30: NORA PELAEZ | D30: 51558286 | E30: 3203337829 | F30: SALITRE | G30: 3 Meses | H30: =IF(G30="","",IF(G30="3 Meses",235000,IF(G30="6 Meses",360000,""))) -> 235000 | I30: Pagado | J30: Wompi | K30: WhatsApp | L30: Anticipo ok
A31: 46260 | B31: Yulianis | C31: YEIMY ANGELICA CUERVO | D31: 42018360 | E31: 3105374194 | F31: NOVACENTRO | G31: 3 Meses | H31: =IF(G31="","",IF(G31="3 Meses",235000,IF(G31="6 Meses",360000,""))) -> 235000 | I31: Pagado | J31: Wompi | K31: WhatsApp | L31: Anticipo ok
A32: 46260 | B32: Stefanya | C32: Giania Marcela Caro | D32: 1016076285 | E32: 3013285879 | F32: SALITRE | G32: 3 Meses | H32: =IF(G32="","",IF(G32="3 Meses",235000,IF(G32="6 Meses",360000,""))) -> 235000 | I32: Pagado | J32: Wompi | K32: WhatsApp | L32: Anticipo ok
... A35: 46261 | B35: Yulianis | C35: JOHANNA ACEVEDO | D35: 1140892094 | E35: 3045775566 | F35: BARRANQUILLA | G35: 3 Meses | H35: =IF(G35="","",IF(G35="3 Meses",235000,IF(G35="6 Meses",360000,""))) -> 235000 | I35: Pagado | J35: Wompi | K35: WhatsApp | L35: Anticipo ok
A36: 46263 | B36: Yulianis | C36: LIA PACHECO | D36: 52273691 | E36: 300 3338332 | F36: SALITRE | G36: 3 Meses | H36: =IF(G36="","",IF(G36="3 Meses",235000,IF(G36="6 Meses",360000,""))) -> 235000 | I36: Pagado | J36: Wompi | K36: WhatsApp | L36: Anticipo ok
A37: 46263 | B37: Stefanya | C37: JULIANA WALKER | D37: 43869251 | E37: 3113498343 | F37: TERRACINA | G37: 3 Meses | H37: =IF(G37="","",IF(G37="3 Meses",235000,IF(G37="6 Meses",360000,""))) -> 235000 | I37: Pagado | J37: Wompi | K37: WhatsApp | L37: Anticipo ok
A38: 46263 | B38: Luisa | C38: CLAUDIA PALMA OROZCO | D38: 32758076 | E38: 300 2244075 | F38: BARRANQUILLA | G38: 3 Meses | H38: =IF(G38="","",IF(G38="3 Meses",235000,IF(G38="6 Meses",360000,""))) -> 235000 | I38: Pagado | J38: Wompi | K38: WhatsApp | L38: Anticipo ok
A39: 46266 | B39: Luisa | C39: Lorena Villega | D39: 30402168 | E39: 310 4354889 | F39: TESORO | G39: 3 Meses | H39: =IF(G39="","",IF(G39="3 Meses",235000,IF(G39="6 Meses",360000,""))) -> 235000 | I39: Pagado | J39: Wompi | K39: WhatsApp | L39: Anticipo ok
H40: =IF(G40="","",IF(G40="3 Meses",235000,IF(G40="6 Meses",360000,"")))
H41: =IF(G41="","",IF(G41="3 Meses",235000,IF(G41="6 Meses",360000,"")))
H42: =IF(G42="","",IF(G42="3 Meses",235000,IF(G42="6 Meses",360000,"")))
...

Sheet COMPROBANTES DE PAG
A1: MARIA VIRGINIA GONZALES
A2: MIGUEL R
A3: MARCELA DIAZ MORON
A4: VERONICA BETANCUR
A5: MAYELI G
A6: LAURA M
A7: CATHERINE GOMEZ
A8: VERONICA MONTEJO
A9: MONICA YEPEZ
A10: FANNY B
A11: LEIDY AGUDELO
A12: JUAN CARLOS GOMEZ
... A39: Lorena Villega
